<?xml version="1.0"?>
<!-- =================================================================================== -->
<!-- |    This document was autogenerated by xacro from XB6.xacro                      | -->
<!-- |    EDITING THIS FILE BY HAND IS NOT RECOMMENDED                                 | -->
<!-- =================================================================================== -->
<!-- XB6 manipulator -->
<robot name="XB6" xmlns:xacro="http://www.ros.org/wiki/xacro">
  <!-- Constants for robot dimensions -->
  <!-- Import all Gazebo-customization elements, including Gazebo colors -->
  <!-- <xacro:include filename="$(find XB6_description)/urdf/XB6.gazebo" />-->
  <!-- Import Rviz colors -->
  <material name="black">
    <color rgba="0.0 0.0 0.0 1.0"/>
  </material>
  <material name="blue">
    <color rgba="0.0 0.0 0.8 1.0"/>
  </material>
  <material name="green">
    <color rgba="0.0 0.8 0.0 1.0"/>
  </material>
  <material name="grey">
    <color rgba="0.2 0.2 0.2 1.0"/>
  </material>
  <material name="orange">
    <color rgba="1.0 0.423529411765 0.0392156862745 1.0"/>
  </material>
  <material name="brown">
    <color rgba="0.870588235294 0.811764705882 0.764705882353 1.0"/>
  </material>
  <material name="red">
    <color rgba="0.8 0.0 0.0 1.0"/>
  </material>
  <material name="white">
    <color rgba="1.0 1.0 1.0 1.0"/>
  </material>
  <!-- Used for fixing robot to Gazebo 'base_link' -->
  <link name="world"/>
  <joint name="fixed" type="fixed">
    <parent link="world"/>
    <child link="XB6_base"/>
  </joint>
  <!--                           base_link                             -->
  <link name="XB6_base">
    <visual>
      <geometry>
        <mesh filename="package://XB6_description/meshes/visual/XB6_base.stl" scale="0.001 0.001 0.001"/>
      </geometry>
      <origin rpy="0 0 0" xyz="0.0 0.0 0.0"/>
      <material name="white"/>
    </visual>
    <inertial>
      <mass value="6.017195265"/>
      <inertia ixx="0.0360869293925" ixy="0.000115216693353" ixz="-1.7544333693e-05" iyy="0.0284183462347" iyz="-1.3689740881e-05" izz="0.0330286412795"/>
      <origin rpy="0 0 0" xyz="0.000196283077 -0.003194724222 0.227348149147"/>
    </inertial>
    <collision>
      <geometry>
        <mesh filename="package://XB6_description/meshes/collision/XB6_base.stl" scale="0.001 0.001 0.001"/>
      </geometry>
      <origin rpy="0 0 0" xyz="0.0 0.0 0.0"/>
    </collision>
  </link>
  <joint name="joint1" type="revolute">
    <parent link="XB6_base"/>
    <child link="XB6_link1"/>
    <limit effort="223.088" lower="-2.9670597284" upper="2.9670597284" velocity="6.544984695"/>
    <axis xyz="0 0 1"/>
    <origin rpy="0 0 0" xyz="0.0 0.0 0.20"/>
  </joint>
  <transmission name="tran1">
    <type>transmission_interface/SimpleTransmission</type>
    <joint name="joint1">
      <hardwareInterface>EffortJointInterface</hardwareInterface>
    </joint>
    <actuator name="motor1">
      <hardwareInterface>EffortJointInterface</hardwareInterface>
      <mechanicalReduction>1</mechanicalReduction>
    </actuator>
  </transmission>
  <!--                                         XB6_link 1                                             -->
  <link name="XB6_link1">
    <visual>
      <geometry>
        <mesh filename="package://XB6_description/meshes/visual/XB6_link1.stl" scale="0.001 0.001 0.001"/>
      </geometry>
      <origin rpy="0 0 0" xyz="0.0 0 0.0"/>
      <material name="white"/>
    </visual>
    <inertial>
      <mass value="5.398500"/>
      <inertia ixx="0.062766" ixy="0.002246" ixz="0.004636" iyy="0.043954" iyz="0.008292" izz="0.330216"/>
      <origin rpy="0 0 0" xyz="0.048526 0.021590 0.105190"/>
    </inertial>
    <collision>
      <geometry>
        <mesh filename="package://XB6_description/meshes/collision/XB6_link1.stl" scale="0.001 0.001 0.001"/>
      </geometry>
      <origin rpy="0 0 0" xyz="0.0 0  0.0"/>
    </collision>
  </link>
  <joint name="joint2" type="revolute">
    <parent link="XB6_link1"/>
    <child link="XB6_link2"/>
    <limit effort="278" lower="-1.6580627894" upper="2.3561944902" velocity="5.235987756"/>
    <axis xyz="0 1 0"/>
    <origin rpy="0 0 0" xyz="0.03 0.0 0.18"/>
  </joint>
  <transmission name="tran2">
    <type>transmission_interface/SimpleTransmission</type>
    <joint name="joint2">
      <hardwareInterface>EffortJointInterface</hardwareInterface>
    </joint>
    <actuator name="motor2">
      <hardwareInterface>EffortJointInterface</hardwareInterface>
      <mechanicalReduction>1</mechanicalReduction>
    </actuator>
  </transmission>
  <!--                                XB6_link 2                    -->
  <link name="XB6_link2">
    <visual>
      <geometry>
        <mesh filename="package://XB6_description/meshes/visual/XB6_link2.stl" scale="0.001 0.001 0.001"/>
      </geometry>
      <origin rpy="0 0 0" xyz="0 0 0.0"/>
      <material name="white"/>
    </visual>
    <inertial>
      <mass value="17.216886"/>
      <inertia ixx="0.322579" ixy="0.000116" ixz="-0.003241" iyy="0.717652" iyz="0.004003" izz="0.079577"/>
      <origin rpy="0 0 0" xyz="-0.002827 0.022603 0.099333"/>
    </inertial>
    <collision>
      <geometry>
        <mesh filename="package://XB6_description/meshes/collision/XB6_link2.stl" scale="0.001 0.001 0.001"/>
      </geometry>
      <origin rpy="0 0 0" xyz="0 0 0.0"/>
    </collision>
  </link>
  <joint name="joint3" type="revolute">
    <parent link="XB6_link2"/>
    <child link="XB6_link3"/>
    <limit effort="210" lower="-3.6651914292" upper="1.1519173063" velocity="6.544984695"/>
    <axis xyz="0 1 0"/>
    <origin rpy="0 0 0" xyz="0.0 0.0 0.34"/>
  </joint>
  <transmission name="tran3">
    <type>transmission_interface/SimpleTransmission</type>
    <joint name="joint3">
      <hardwareInterface>EffortJointInterface</hardwareInterface>
    </joint>
    <actuator name="motor3">
      <hardwareInterface>EffortJointInterface</hardwareInterface>
      <mechanicalReduction>1</mechanicalReduction>
    </actuator>
  </transmission>
  <link name="XB6_link3">
    <visual>
      <geometry>
        <mesh filename="package://XB6_description/meshes/visual/XB6_link3.stl" scale="0.001 0.001 0.001"/>
      </geometry>
      <origin rpy="0 0 0" xyz="0.0 0.0 0.0"/>
      <material name="white"/>
    </visual>
    <inertial>
      <mass value="6.795353"/>
      <inertia ixx="0.012171" ixy="0.000103" ixz="0.006378" iyy="0.319676" iyz="0.000070" izz="0.027475"/>
      <origin rpy="0 0 0" xyz="0.035922 0.000116 0.009259"/>
    </inertial>
    <collision>
      <geometry>
        <mesh filename="package://XB6_description/meshes/collision/XB6_link3.stl" scale="0.001 0.001 0.001"/>
      </geometry>
      <origin rpy="0 0 0" xyz="0.0 0.0 0.0"/>
    </collision>
  </link>
  <joint name="joint4" type="revolute">
    <parent link="XB6_link3"/>
    <child link="XB6_link4"/>
    <limit effort="77.355" lower="-2.9670597284" upper="2.9670597284" velocity="6.544984695"/>
    <!--     lower="-2.79" upper="2.79" -->
    <axis xyz="1 0 0"/>
    <!--     <origin rpy="0 0 0" xyz="0.149734 0.0 0.07"/> -->
    <origin rpy="0 0 0" xyz="0.12 0.0 0.035"/>
  </joint>
  <transmission name="tran4">
    <type>transmission_interface/SimpleTransmission</type>
    <joint name="joint4">
      <hardwareInterface>EffortJointInterface</hardwareInterface>
    </joint>
    <actuator name="motor4">
      <hardwareInterface>EffortJointInterface</hardwareInterface>
      <mechanicalReduction>1</mechanicalReduction>
    </actuator>
  </transmission>
  <link name="XB6_link4">
    <visual>
      <geometry>
        <mesh filename="package://XB6_description/meshes/visual/XB6_link4.stl" scale="0.001 0.001 0.001"/>
      </geometry>
      <origin rpy="0 0 0" xyz="0.0 0.0 0.0"/>
      <material name="white"/>
    </visual>
    <inertial>
      <mass value="3.999356"/>
      <inertia ixx="0.167289" ixy="0.002181" ixz="-0.000006" iyy="0.020615" iyz="0.000031" izz="0.025169"/>
      <origin rpy="0 0 0" xyz="0.120344 0.004572 -0.000141"/>
    </inertial>
    <collision>
      <geometry>
        <mesh filename="package://XB6_description/meshes/collision/XB6_link4.stl" scale="0.001 0.001 0.001"/>
      </geometry>
      <origin rpy="0 0 0" xyz="0.0 0.0 0.0"/>
    </collision>
  </link>
  <joint name="joint5" type="revolute">
    <parent link="XB6_link4"/>
    <child link="XB6_link5"/>
    <limit effort="44.3232" lower="-2.3561944902" upper="2.3561944902" velocity="6.7020643277"/>
    <axis xyz="0 1 0"/>
    <origin rpy="0 0 0" xyz="0.225 0.0 0.0"/>
  </joint>
  <transmission name="tran5">
    <type>transmission_interface/SimpleTransmission</type>
    <joint name="joint5">
      <hardwareInterface>EffortJointInterface</hardwareInterface>
    </joint>
    <actuator name="motor5">
      <hardwareInterface>EffortJointInterface</hardwareInterface>
      <mechanicalReduction>1</mechanicalReduction>
    </actuator>
  </transmission>
  <link name="XB6_link5">
    <visual>
      <geometry>
        <mesh filename="package://XB6_description/meshes/visual/XB6_link5.stl" scale="0.001 0.001 0.001"/>
      </geometry>
      <origin rpy="0 0 0" xyz="0 0 0"/>
      <material name="white"/>
    </visual>
    <inertial>
      <mass value="2.484109"/>
      <inertia ixx="0.001308" ixy="-0.000005" ixz="-0.000063" iyy="0.035775" iyz="0.000005" izz="0.006039"/>
      <origin rpy="0 0 0" xyz="0.004529 0.000438 0.000626"/>
    </inertial>
    <collision>
      <geometry>
        <mesh filename="package://XB6_description/meshes/collision/XB6_link5.stl" scale="0.001 0.001 0.001"/>
      </geometry>
      <origin rpy="0 0 0" xyz="0 0 0"/>
    </collision>
  </link>
  <joint name="joint6" type="revolute">
    <parent link="XB6_link5"/>
    <child link="XB6_link6"/>
    <limit effort="29.925" lower="-6.2831853072" upper="6.2831853072" velocity="10.471975512"/>
    <axis xyz="1 0 0"/>
    <origin rpy="0.0 0.0 0.0" xyz="0.090 0.0 0.0"/>
  </joint>
  <transmission name="tran6">
    <type>transmission_interface/SimpleTransmission</type>
    <joint name="joint6">
      <hardwareInterface>EffortJointInterface</hardwareInterface>
    </joint>
    <actuator name="motor6">
      <hardwareInterface>EffortJointInterface</hardwareInterface>
      <mechanicalReduction>1</mechanicalReduction>
    </actuator>
  </transmission>
  <link name="XB6_link6">
    <visual>
      <geometry>
        <mesh filename="package://XB6_description/meshes/visual/XB6_link6.stl" scale="0.001 0.001 0.001"/>
      </geometry>
      <origin rpy="0 0 0" xyz="0.0 0.0 0.0"/>
      <material name="white"/>
    </visual>
    <inertial>
      <mass value="0.048215"/>
      <inertia ixx="0.007264" ixy="-0.000000" ixz="-0.000000" iyy="0.000007" iyz="-0.000000" izz="0.000007"/>
      <origin rpy="0 0 0" xyz="0.003183 -0.000000 -0.000118"/>
    </inertial>
    <collision>
      <geometry>
        <mesh filename="package://XB6_description/meshes/collision/XB6_link6.stl" scale="0.001 0.001 0.001"/>
      </geometry>
      <origin rpy="0 0 0" xyz="0.0 0.0 0.0"/>
    </collision>
  </link>



</robot>

